<?xml version="1.0" ?>
<!-- =================================================================================== -->
<!-- |    This document was autogenerated by xacro from agv.urdf.xacro                 | -->
<!-- |    EDITING THIS FILE BY HAND IS NOT RECOMMENDED                                 | -->
<!-- =================================================================================== -->
<robot name="AGV-OTA">
  <property name="M_PI" value="3.1415926535897931"/>
  <!-- see https://secure.wikimedia.org/wikipedia/en/wiki/List_of_moment_of_inertia_tensors -->
  <property name="M_PI" value="3.1415926535897931"/>
  <link name="base_link">
    <origin rpy=" 0 0 0" xyz="0.05 0 0.05"/>
    <visual>
      <origin rpy=" 0 0 0" xyz="0.05 0 -0.08"/>
      <geometry>
        <mesh filename="package://teknofest_industrial_tech/meshes/sanayi.dae" scale="0.001 0.001 0.001"/>
        <!-- <box size="0.55 0.4 0.12"/> -->
      </geometry>
    </visual>
    <collision>
      <origin rpy=" 0 0 0" xyz="0.05 0 0.05"/>
      <geometry>
        <!-- <mesh filename="package://teknofest_industrial_tech/meshes/robot.stl" scale="0.001 0.001 0.001"/> -->
        <box size="0.55 0.4 0.12"/>
      </geometry>
    </collision>
    <inertial>
      <mass value="1.0"/>
      <origin xyz="0 0 0"/>
      <inertia ixx="0.051665312667199995" ixy="0.0" ixz="0.0" iyy="0.09523151211571325" iyz="0.0" izz="0.13189683078291323"/>
    </inertial>
  </link>

  <!-- <gazebo reference="base_link">
    <material value="Gazebo/Orange"/>
  </gazebo> -->

  <!-- Laser -->
  <link name="scan_link">
    <visual>
      <origin rpy="1.570796 0 -1.57" xyz="0 0 0"/>
      <geometry>
        <mesh filename="package://industrial_pack/meshes/OTAv07_meshes/S30B-XXXXXX.stl" scale="0.001 0.001 0.001"/>
      </geometry>
    </visual>
    <!--<collision>
        <origin xyz="0 0 0.0" rpy="1.570796 0 -1.570796"/>
        <geometry>
          <mesh filename="package://agv_description/meshes/OTAv07_meshes/S30B-XXXXXX.stl" scale="0.001 0.001 0.001"/> 
        </geometry>
      </collision>  -->
  </link>

  <joint name="scan_joint" type="fixed">
    <origin rpy="0 0 3.14" xyz="0.35 0.0 0.15"/>
    <parent link="base_link"/>
    <child link="scan_link"/>
    <axis xyz="0 0 1"/>
  </joint>

  <gazebo reference="scan_link">
    <material value="Gazebo/DarkGray"/>
    <sensor name="laser_scan" type="ray">
      <tf_prefix/>
      <pose>0 0 0 0 0 0</pose>
      <visualize>false</visualize>
      <update_rate>40</update_rate>
      <ray>
        <scan>
          <horizontal>
            <samples>720</samples>
            <resolution>1</resolution>
            <min_angle>-3.14</min_angle>
            
            <max_angle>3.14</max_angle>
          </horizontal>
        </scan>
        <range>
          <min>0.10</min>
          <max>30.0</max>
          <resolution>0.03</resolution>
        </range>
        <noise>
          <type>gaussian</type>
          <mean>0.0</mean>
          <stddev>0.01</stddev>
        </noise>
      </ray>
      <plugin filename="libgazebo_ros_laser.so" name="laser_scan_plugin">
        <topicName>scan</topicName>
        <frameName>scan_link</frameName>
        <tf_prefix>/</tf_prefix>
      </plugin>
    </sensor>
  </gazebo>

<link name="camera_link">
    <visual> 
      <geometry> 
        <box size="0.05 0.2 0.05"/>
      </geometry> 
    </visual> 
</link>

<!-- camera link joint -->
  <joint name="camera_joint" type="fixed">
  <parent link="base_link" />
  <child link="camera_link" />
  <origin xyz="0.42 0 0.07"  rpy="0 0.35 0" />
  <axis xyz="0 0 1" />
</joint>

<joint name="camera_optical_joint" type="fixed">
<origin xyz="0.1 0 0" rpy="-1.57 0 -1.57"/>
<parent link="camera_link"/>
<child link="camera_link_optical"/>
</joint>

<link name="camera_link_optical">
</link>

<gazebo reference="camera_link">
  <sensor name="camera" type="depth">
    <pose>0 0 0 0 0 0</pose>
    <!-- <pose>0.3 0 0.21 0 0.45 0</pose> -->
    <update_rate>30</update_rate>
    <camera>
      <horizontal_fov>1.01229</horizontal_fov>
      <image>
        <width>1280</width>
        <height>720</height>
        <format>R8G8B8</format>
      </image>
      <clip>
        <near>0.1</near>
        <far>30</far>
      </clip>
    </camera>
    <plugin name="camera_plugin" filename="libgazebo_ros_openni_kinect.so">
      <baseline>0.2</baseline>
      <alwaysOn>true</alwaysOn>
      <updateRate>0.0</updateRate>
      <cameraName>camera_ir</cameraName>
      <imageTopicName>/camera/color/image_raw</imageTopicName>
      <cameraInfoTopicName>/camera/color/camera_info</cameraInfoTopicName>
      <depthImageTopicName>/camera/depth/image_raw</depthImageTopicName>
      <depthImageCameraInfoTopicName>/camera/depth/camera_info</depthImageCameraInfoTopicName>
      <pointCloudTopicName>/camera/depth/points</pointCloudTopicName>
      <frameName>camera_link_optical</frameName>
      <pointCloudCutoff>0.2</pointCloudCutoff>
      <pointCloudCutoffMax>5.5</pointCloudCutoffMax>
      <distortionK1>0</distortionK1>
      <distortionK2>0</distortionK2>
      <distortionK3>0</distortionK3>
      <distortionT1>0</distortionT1>
      <distortionT2>0</distortionT2>
      <CxPrime>0</CxPrime>
      <Cx>0</Cx>
      <Cy>0</Cy>
      <focalLength>0</focalLength>
      <hackBaseline>0</hackBaseline>
    </plugin>
  </sensor>
</gazebo>

<link name="qr_camera_link">
  <visual> 
    <geometry> 
      <box size="0.01 0.1 0.01"/>
    </geometry> 
  </visual> 
</link>

<!-- qr camera link joint -->
<joint name="qr_camera_joint" type="fixed">
  <parent link="base_link" />
  <child link="qr_camera_link" />
  <origin xyz="0.45 -0.15 0.0"  rpy="0 0.9 0" />
  <axis xyz="0 0 1" />
</joint>

<joint name="qr_camera_optical_joint" type="fixed">
  <origin xyz="0.1 0 0" rpy="-1.57 0 -1.57"/>
  <parent link="qr_camera_link"/>
  <child link="qr_camera_link_optical"/>
  </joint>

  <link name="qr_camera_link_optical">
  </link>

  <!-- camera -->
  <gazebo reference="qr_camera_link">
    <sensor type="camera" name="camera1">
      <update_rate>30.0</update_rate>
      <camera name="head">
        <horizontal_fov>1.3962634</horizontal_fov>
        <image>
          <width>800</width>
          <height>800</height>
          <format>R8G8B8</format>
        </image>
        <clip>
          <near>0.02</near>
          <far>300</far>
        </clip>
        <noise>
          <type>gaussian</type>
          <!-- Noise is sampled independently per pixel on each frame.
               That pixel's noise value is added to each of its color
               channels, which at that point lie in the range [0,1]. -->
          <mean>0.0</mean>
          <stddev>0.007</stddev>
        </noise>
      </camera>
      <plugin name="camera_controller" filename="libgazebo_ros_camera.so">
        <alwaysOn>true</alwaysOn>
        <updateRate>0.0</updateRate>
        <cameraName>qr/camera1</cameraName>
        <imageTopicName>qr/image_raw</imageTopicName>
        <cameraInfoTopicName>qr/camera_info</cameraInfoTopicName>
        <frameName>qr_camera_link_optical</frameName>
        <hackBaseline>0.07</hackBaseline>
        <distortionK1>0.0</distortionK1>
        <distortionK2>0.0</distortionK2>
        <distortionK3>0.0</distortionK3>
        <distortionT1>0.0</distortionT1>
        <distortionT2>0.0</distortionT2>
      </plugin>
    </sensor>
  </gazebo>

  <!-- IMU Link -->
  <link name="imu_link"/>
  <joint name="imu_joint" type="fixed">
    <parent link="base_link"/>
    <child link="imu_link"/>
    <origin rpy="0 0 0" xyz="0.0 0 0.068"/>
  </joint>

  <!-- <link name="ir1_link">
    <inertial>
      <origin rpy="0 0 0" xyz="0 0 0"/>
      <mass value="0.001"/>
      <inertia ixx="0.001666" ixy="0" ixz="0" iyy="0.001666" iyz="0" izz="0.001666"/>
    </inertial>
    <visual>
      <origin rpy="0 0 0" xyz="0 0 0"/>
      <geometry>
        <mesh filename="package://agv_description/meshes/OTAv07_meshes/FotoelektrikSensor.stl" scale="0.0015 0.0015 0.0015"/>
      </geometry>
    </visual>
    <collision>
      <origin rpy="0 0 0" xyz="0 0 0"/>
      <geometry>
        <box size="0.01 0.01 0.01"/>
      </geometry>
    </collision>
  </link>

  <joint name="ir1_joint" type="fixed">
    <origin rpy="0 0 0" xyz="0.505 0.215 -0.03"/>
    <parent link="base_link"/>
    <child link="ir1_link"/>
  </joint>

  <gazebo reference="ir1_link">
    <sensor name="ir1" type="ray">
      <pose>0 0 0 0 0 0</pose>
      <ray>
        <scan>
          <horizontal>
            <samples>320</samples>
            <resolution>1</resolution>
            <min_angle>-0.001</min_angle>
            <max_angle>0.001</max_angle>
          </horizontal>
        </scan>
        <range>
          <min>0.02</min>
          <max>5.0</max>
          <resolution>0.01</resolution>
        </range>
      </ray>
      <plugin filename="libgazebo_ros_range.so" name="gazebo_ros_range">
        <topicName>ir1</topicName>
        <frameName>ir1_link</frameName>
        <frameId>ir1_link</frameId>
        <radiation>ultrasound</radiation>
        <fov>0.7</fov>
        <gaussianNoise>0</gaussianNoise>
      </plugin>
      <always_on>1</always_on>
      <update_rate>4</update_rate>
      <visualize>false</visualize>
    </sensor>
  </gazebo>
 -->
  
  <link name="wheel_left_link">
    <visual>
      <origin rpy=" 0 0 1.570796" xyz="0 0 0"/>
      <geometry>
        <mesh filename="package://industrial_pack/meshes/OTAv07_meshes/AnaTeker.stl" scale="0.001 0.001 0.001"/>
      </geometry>
    </visual>
    <collision>
      <origin rpy="0 1.570796 1.570796" xyz="0 0 0"/>
      <geometry>
        <cylinder length="0.05" radius="0.1"/>
      </geometry>
    </collision>
    <inertial>
      <mass value="0.1"/>
      <origin xyz="0 0 0"/>
      <inertia ixx="0.0005658331069999999" ixy="0.0" ixz="0.0" iyy="0.0005658331069999999" iyz="0.0" izz="0.001125"/>
    </inertial>
  </link>
  <joint name="wheel_left_base" type="continuous">
    <origin rpy="0 0 0" xyz="-0.2 -0.19 -0.06"/>
    <parent link="base_link"/>
    <child link="wheel_left_link"/>
    <axis xyz="0 1 0"/>
  </joint>
  <gazebo reference="wheel_left_link">
    <material value="Gazebo/Green"/>
  </gazebo>
  <link name="wheel_right_link">
    <visual>
      <origin rpy=" 0 0 1.570796" xyz="0 0 0"/>
      <geometry>
        <mesh filename="package://industrial_pack/meshes/OTAv07_meshes/AnaTeker.stl" scale="0.001 0.001 0.001"/>
      </geometry>
    </visual>
    <collision>
      <origin rpy="0 1.570796 1.570796" xyz="0 0 0"/>
      <geometry>
        <cylinder length="0.05" radius="0.1"/>
      </geometry>
    </collision>
    <inertial>
      <mass value="0.1"/>
      <origin xyz="0 0 0"/>
      <inertia ixx="0.0005658331069999999" ixy="0.0" ixz="0.0" iyy="0.0005658331069999999" iyz="0.0" izz="0.001125"/>
    </inertial>
  </link>
  <joint name="wheel_right_base" type="continuous">
    <origin rpy="0 0 0" xyz="-0.2 0.19 -0.06"/>
    <parent link="base_link"/>
    <child link="wheel_right_link"/>
    <axis xyz="0 1 0"/>
  </joint>

  <gazebo reference="wheel_right_link">
    <material value="Gazebo/Green"/>
  </gazebo>

  <link name="caster_front_right_link">
    <visual>
      <origin rpy=" 0 0 0" xyz="0 0 0"/>
      <geometry>
        <mesh filename="package://industrial_pack/meshes/OTAv07_meshes/SarhosTeker.stl" scale="0.001 0.001 0.001"/>
      </geometry>
    </visual>
    <collision>
      <origin rpy="0 0 0" xyz="0 0 0"/>
      <geometry>
        <cylinder length="0.07" radius="0.005"/>
      </geometry>
    </collision>
    <inertial>
      <mass value="0.1"/>
      <origin xyz="0 0 0"/>
      <inertia ixx="4.145831675000001e-05" ixy="0.0" ixz="0.0" iyy="4.145831675000001e-05" iyz="0.0" izz="1.25e-06"/>
    </inertial>
  </link>

  <joint name="caster_front_right_joint" type="continuous">
    <origin rpy="0 0 0" xyz="0.27 -0.15 -0.048"/>
    <axis xyz="0 0 1"/>
    <anchor xyz="0 0 0"/>
    <limit effort="0" k_velocity="0" velocity="0"/>
    <joint_properties damping="0.0" friction="0.0"/>
    <parent link="base_link"/>
    <child link="caster_front_right_link"/>
  </joint>

  <gazebo reference="caster_front_right_link">
    <material value="Gazebo/Gray"/>
  </gazebo>

  <link name="caster_wheel_front_right_link">
    <collision>
      <origin rpy="0 1.570796 1.570796" xyz="0 0 0"/>
      <geometry>
        <cylinder length="0.02" radius="0.042"/>
      </geometry>
    </collision>
    <inertial>
      <mass value="0.1"/>
      <origin xyz="0 0 0"/>
      <inertia ixx="4.7433314360000004e-05" ixy="0.0" ixz="0.0" iyy="4.7433314360000004e-05" iyz="0.0" izz="8.820000000000002e-05"/>
    </inertial>
  </link>

  <joint name="caster_front_right_wheel_joint" type="continuous">
    <axis xyz="0 1 0"/>
    <origin rpy="0 0 0" xyz="-0.04 0 -0.07"/>
    <parent link="caster_front_right_link"/>
    <child link="caster_wheel_front_right_link"/>
  </joint>

  <link name="caster_front_left_link">
    <visual>
      <origin rpy=" 0 0 0" xyz="0 0 0"/>
      <geometry>
        <mesh filename="package://industrial_pack/meshes/OTAv07_meshes/SarhosTeker.stl" scale="0.001 0.001 0.001"/>
      </geometry>
    </visual>
    <collision>
      <origin rpy="0 0 0" xyz="0 0 0"/>
      <geometry>
        <cylinder length="0.07" radius="0.005"/>
      </geometry>
    </collision>
    <inertial>
      <mass value="0.1"/>
      <origin xyz="0 0 0"/>
      <inertia ixx="4.145831675000001e-05" ixy="0.0" ixz="0.0" iyy="4.145831675000001e-05" iyz="0.0" izz="1.25e-06"/>
    </inertial>
  </link>

  <joint name="caster_front_left_joint" type="continuous">
    <origin rpy="0 0 0" xyz="0.27 0.15 -0.048"/>
    <axis xyz="0 0 1"/>
    <anchor xyz="0 0 0"/>
    <limit effort="0" k_velocity="0" velocity="0"/>
    <joint_properties damping="0.0" friction="0.0"/>
    <parent link="base_link"/>
    <child link="caster_front_left_link"/>
  </joint>

  <gazebo reference="caster_front_left_link">
    <material value="Gazebo/Gray"/>
  </gazebo>
  <link name="caster_wheel_front_left_link">
    <collision>
      <origin rpy="0 1.570796 1.570796" xyz="0 0 0"/>
      <geometry>
        <cylinder length="0.02" radius="0.042"/>
      </geometry>
    </collision>
    <inertial>
      <mass value="0.1"/>
      <origin xyz="0 0 0"/>
      <inertia ixx="4.7433314360000004e-05" ixy="0.0" ixz="0.0" iyy="4.7433314360000004e-05" iyz="0.0" izz="8.820000000000002e-05"/>
    </inertial>
  </link>
  <joint name="caster_front_left_wheel_joint" type="continuous">
    <axis xyz="0 1 0"/>
    <origin rpy="0 0 0" xyz="-0.04 0 -0.07"/>
    <parent link="caster_front_left_link"/>
    <child link="caster_wheel_front_left_link"/>
  </joint>
  <!-- <link name="caster_back_right_link">
    <visual>
      <origin rpy=" 0 0 0" xyz="0 0 0"/>
      <geometry>
        <mesh filename="package://agv_description/meshes/OTAv07_meshes/SarhosTeker.stl" scale="0.001 0.001 0.001"/>
      </geometry>
    </visual>
    <collision>
      <origin rpy="0 0 0" xyz="0 0 0"/>
      <geometry>
        <cylinder length="0.07" radius="0.005"/>
      </geometry>
    </collision>
    <inertial>
      <mass value="0.1"/>
      <origin xyz="0 0 0"/>
      <inertia ixx="4.145831675000001e-05" ixy="0.0" ixz="0.0" iyy="4.145831675000001e-05" iyz="0.0" izz="1.25e-06"/>
    </inertial>
  </link>
  <joint name="caster_back_right_joint" type="continuous">
    <origin rpy="0 0 0" xyz="-0.37 -0.22 -0.048"/>
    <axis xyz="0 0 1"/>
    <anchor xyz="0 0 0"/>
    <limit effort="0" k_velocity="0" velocity="0"/>
    <joint_properties damping="0.0" friction="0.0"/>
    <parent link="base_link"/>
    <child link="caster_back_right_link"/>
  </joint>
  <gazebo reference="caster_back_right_link">
    <material value="Gazebo/Gray"/>
  </gazebo>
  <link name="caster_wheel_back_right_link">
    <collision>
      <origin rpy="0 1.570796 1.570796" xyz="0 0 0"/>
      <geometry>
        <cylinder length="0.02" radius="0.042"/>
      </geometry>
    </collision>
    <inertial>
      <mass value="0.1"/>
      <origin xyz="0 0 0"/>
      <inertia ixx="4.7433314360000004e-05" ixy="0.0" ixz="0.0" iyy="4.7433314360000004e-05" iyz="0.0" izz="8.820000000000002e-05"/>
    </inertial>
  </link>
  <joint name="caster_back_right_wheel_joint" type="continuous">
    <axis xyz="0 1 0"/>
    <origin rpy="0 0 0" xyz="-0.04 0 -0.07"/>
    <parent link="caster_back_right_link"/>
    <child link="caster_wheel_back_right_link"/>
  </joint>
  <link name="caster_back_left_link">
    <visual>
      <origin rpy=" 0 0 0" xyz="0 0 0"/>
      <geometry>
        <mesh filename="package://agv_description/meshes/OTAv07_meshes/SarhosTeker.stl" scale="0.001 0.001 0.001"/>
      </geometry>
    </visual>
    <collision>
      <origin rpy="0 0 0" xyz="0 0 0"/>
      <geometry>
        <cylinder length="0.07" radius="0.005"/>
      </geometry>
    </collision>
    <inertial>
      <mass value="0.1"/>
      <origin xyz="0 0 0"/>
      <inertia ixx="4.145831675000001e-05" ixy="0.0" ixz="0.0" iyy="4.145831675000001e-05" iyz="0.0" izz="1.25e-06"/>
    </inertial>
  </link>

  <joint name="caster_back_left_joint" type="continuous">
    <origin rpy="0 0 0" xyz="-0.37 0.22 -0.048"/>
    <axis xyz="0 0 1"/>
    <anchor xyz="0 0 0"/>
    <limit effort="0" k_velocity="0" velocity="0"/>
    <joint_properties damping="0.0" friction="0.0"/>
    <parent link="base_link"/>
    <child link="caster_back_left_link"/>
  </joint>

  <gazebo reference="caster_back_left_link">
    <material value="Gazebo/Gray"/>
  </gazebo>

  <link name="caster_wheel_back_left_link">
    <collision>
      <origin rpy="0 1.570796 1.570796" xyz="0 0 0"/>
      <geometry>
        <cylinder length="0.02" radius="0.042"/>
      </geometry>
    </collision>
    <inertial>
      <mass value="0.1"/>
      <origin xyz="0 0 0"/>
      <inertia ixx="4.7433314360000004e-05" ixy="0.0" ixz="0.0" iyy="4.7433314360000004e-05" iyz="0.0" izz="8.820000000000002e-05"/>
    </inertial>
  </link>

  <joint name="caster_back_left_wheel_joint" type="continuous">
    <axis xyz="0 1 0"/>
    <origin rpy="0 0 0" xyz="-0.04 0 -0.07"/>
    <parent link="caster_back_left_link"/>
    <child link="caster_wheel_back_left_link"/>
  </joint> -->

  <gazebo>
    <plugin filename="libgazebo_ros_diff_drive.so" name="differential_drive_controller">
      <rosDebugLevel>Debug</rosDebugLevel>
      <publishWheelTF>false</publishWheelTF>
      <publishOdomTF>false</publishOdomTF>
      <publishWheelJointState>true</publishWheelJointState>
      <alwaysOn>true</alwaysOn>
      <leftJoint>wheel_right_base</leftJoint>
      <rightJoint>wheel_left_base</rightJoint>
      <wheelSeparation>0.60</wheelSeparation>
      <wheelDiameter>0.20</wheelDiameter>
      <wheelTorque>20</wheelTorque>
      <wheelAcceleration>1.8</wheelAcceleration>
      <commandTopic>cmd_vel</commandTopic>
      <odometryTopic>odom</odometryTopic>
      <odometryFrame>odom</odometryFrame>
      <odometrySource>world</odometrySource>
      <robotBaseFrame>base_link</robotBaseFrame>
      <legacyMode>true</legacyMode>
      <publishTf>true</publishTf>
      <updateRate>150.0</updateRate>
    </plugin>
  </gazebo>

  <gazebo>
    <plugin filename="libgazebo_ros_joint_state_publisher.so" name="joint_state_publisher">
      <jointName>caster_front_left_joint,caster_front_right_joint,caster_front_left_wheel_joint,caster_front_right_wheel_joint</jointName>
      <updateRate>10.0</updateRate>
      <alwaysOn>true</alwaysOn>
    </plugin>
  </gazebo>
  
  <gazebo>
    <plugin filename="libgazebo_ros_imu.so" name="imu_plugin">
      <alwaysOn>true</alwaysOn>
      <bodyName>imu_link</bodyName>
      <frameName>imu_link</frameName>
      <topicName>imu_data_raw</topicName>
      <serviceName>imu_service</serviceName>
      <gaussianNoise>0.0</gaussianNoise>
      <updateRate>200</updateRate>
      <imu>
        <noise>
          <type>gaussian</type>
          <rate>
            <mean>0.0</mean>
            <stddev>2e-4</stddev>
            <bias_mean>0.0000075</bias_mean>
            <bias_stddev>0.0000008</bias_stddev>
          </rate>
          <accel>
            <mean>0.0</mean>
            <stddev>1.7e-2</stddev>
            <bias_mean>0.1</bias_mean>
            <bias_stddev>0.001</bias_stddev>
          </accel>
        </noise>
      </imu>
    </plugin>
  </gazebo>
</robot>
